Workbook

Sheet Endpoints for Plants & Aquatics
A1: Updated 10/17/2025 | G1: Blue Shading = Manual entry; Green Shading = Automated; ONLY INPUT DEFINITIVE VALUES
C2: Enter toxicity inputs | D2: Test species | E2: Test Species Notes: | F2: MRID(s) | G2: Non-Listed Taxa | J2: Listed Individuals (NE/MA/NLAA/LAA) | M2: Listed Populations (J/AM) | P2: Community-Level (as needed) | S2: Additional Comments:
G3: Operator = />/< | H3: Value | I3: Type | J3: Operator = />/< | K3: Value | L3: Type | M3: Operator = />/< | N3: Value | O3: Type | P3: Operator = />/< | Q3: Value | R3: Type | AZ3: LOOKUP VALUES
A4: Aquatic Vertebrates | B4: FW Fish | C4: FW Acute (µg a.i./L) | D4: Fathead minnow (Pimephales promelas) | G4: = | H4: 100 | I4: LC50 | J4: =IF(G4="","",G4) -> = | K4: =IF((LEN(TRIM(H4))=0),"--",H4) -> 100 | L4: LC50 | M4: =G4 -> = | N4: =IF((LEN(TRIM(H4))=0),"Enter LC50 in Column H",H4*0.5) -> 50 | O4: 0.5 * LC50 or HC05 | Q4: 100 | R4: LC50 or HC25 | AZ4: Operators | BB4: Test Species > | BC4: None Available
C5: FW Chronic (ug a.i./L) | G5: > | H5: 0.1 | I5: NOAEC | J5: =IF(G5="","",G5) -> > | K5: =IF((LEN(TRIM(H5))=0),"--",H5) -> 0.1 | L5: NOAEC | M5: =IF(AND(G5="=",G6="="),G5,(IF(G5="<",G5,G6))) -> = | N5: =IF(OR(H5="",H6=""),"Enter NOAEC & LOAEC in Column H", (GEOMEAN(H5:H6))) -> 1.5811388 | O5: MATC | AZ5: = | BC5: Other
G6: = | H6: 25 | I6: LOAEC | K6: =IFERROR(IF(OR(H5="",H6=""),"Check NOAEC and LOAEC Data Entry",GEOMEAN(H5:H6)),"Check NOAEC and LOAEC Data Entry") -> 1.5811388 | L6: MATC | AZ6: > | BC6: Multiple - SSD
B7: EM Fish | C7: FW Acute (µg a.i./L) | G7: > | H7: 26 | I7: LC50 | J7: =IF(G7="","",G7) -> > | K7: =IF((LEN(TRIM(H7))=0),"--",H7) -> 26 | L7: LC50 | M7: =G7 -> > | N7: =IF((LEN(TRIM(H7))=0),"Enter LC50 in Column H",H7*0.5) -> 13 | O7: 0.5 * LC50 or HC05 | Q7: 26 | R7: LC50 or HC25 | AZ7: < | BC7: Anodonta sp.
C8: FW Chronic (ug a.i./L) | H8: 2 | I8: NOAEC | J8: =IF(G8="","",G8) | K8: =IF((LEN(TRIM(H8))=0),"--",H8) -> 2 | L8: NOAEC | M8: =IF(AND(G8="=",G9="="),G8,(IF(G8="<",G8,G9))) -> 0 | N8: =IF(OR(H8="",H9=""),"Enter NOAEC & LOAEC in Column H", (GEOMEAN(H8:H9))) -> 3.7416574 | O8: MATC | BC8: Uca pugilator
H9: 7 | I9: LOAEC | K9: =IFERROR(IF(OR(H8="",H9=""),"Check NOAEC and LOAEC Data Entry",GEOMEAN(H8:H9)),"Check NOAEC and LOAEC Data Entry") -> 3.7416574 | L9: MATC | BC9: Aedes taeniorhynchus
B10: Amphibian (or Fish) | C10: FW Acute (µg a.i./L) | H10: 4 | I10: LC50 | J10: =IF(G10="","",G10) | K10: =IF((LEN(TRIM(H10))=0),"--",H10) -> 4 | L10: LC50 | M10: =G10 -> 0 | N10: =IF((LEN(TRIM(H10))=0),"Enter LC50 in Column H",H10*0.5) -> 2 | O10: 0.5 * LC50 or HC05 | Q10: 4 | R10: LC50 or HC25 | BC10: Allolobophora tuberculata
C11: FW Chronic (ug a.i./L) | H11: 1 | I11: NOAEC | J11: =IF(G11="","",G11) | K11: =IF((LEN(TRIM(H11))=0),"--",H11) -> 1 | L11: NOAEC | M11: =IF(AND(G11="=",G12="="),G11,(IF(G11="<",G11,G12))) -> 0 | N11: =IF(OR(H11="",H12=""),"Enter NOAEC & LOAEC in Column H", (GEOMEAN(H11:H12))) -> 2.6457513 | O11: MATC | BC11: Americamysis bahia
H12: 7 | I12: LOAEC | K12: =IFERROR(IF(OR(H11="",H12=""),"Check NOAEC and LOAEC Data Entry",GEOMEAN(H11:H12)),"Check NOAEC and LOAEC Data Entry") -> 2.6457513 | L12: MATC | BC12: Aphidius rhopalosiphi
A13: Aquatic Invertebrates | B13: Water Column Invertebrate (Non-Specific) Endpoints | C13: Acute Freshwater (µg a.i./L) | D13: Daphnia magna | H13: 200 | I13: EC/LC50 | J13: =IF(G13="","",G13) | K13: =IF((LEN(TRIM(H13))=0),"--",H13) -> 200 | L13: LC50 | M13: =G13 -> 0 | N13: =IF((LEN(TRIM(H13))=0),"Enter LC50 in Column H",H13*0.5) -> 100 | O13: 0.5 * LC50 or HC05 | Q13: 200 | R13: LC50 or HC25 | BC13: Apis mellifera
C14: Chronic Freshwater (µg a.i./L) | D14: Daphnia magna | G14: > | H14: 0.1 | I14: NOAEC | J14: =IF(G14="","",G14) -> > | K14: =IF((LEN(TRIM(H14))=0),"--",H14) -> 0.1 | L14: NOAEC | M14: =IF(AND(G14="=",G15="="),G14,(IF(G14="<",G14,G15))) -> = | N14: =IF(OR(H14="",H15=""),"Enter NOAEC & LOAEC in Column H", (GEOMEAN(H14:H15))) -> 0.70710678 | O14: MATC | BC14: Bombus impatiens
G15: = | H15: 5 | I15: LOAEC | K15: =IFERROR(IF(OR(H14="",H15=""),"Check NOAEC and LOAEC Data Entry",GEOMEAN(H14:H15)),"Check NOAEC and LOAEC Data Entry") -> 0.70710678 | L15: MATC | BC15: Bombus terrestris
C16: Acute Estuarine/Marine (µg a.i./L) | D16: Americamysis bahia | G16: > | H16: 0.01 | I16: LC50 | J16: =IF(G16="","",G16) -> > | K16: =IF((LEN(TRIM(H16))=0),"--",H16) -> 0.01 | L16: LC50 | M16: =G16 -> > | N16: =IF((LEN(TRIM(H16))=0),"Enter LC50 in Column H",H16*0.5) -> 0.005 | O16: 0.5 * LC50 or HC05 | Q16: 0.01 | R16: LC50 or HC25 | BC16: Brachionus calyciflorus
C17: Chronic Estuarine/Marine (µg a.i./L) | D17: Americamysis bahia | H17: 2 | I17: NOAEC | J17: =IF(G17="","",G17) | K17: =IF((LEN(TRIM(H17))=0),"--",H17) -> 2 | L17: NOAEC | M17: =IF(AND(G17="=",G18="="),G17,(IF(G17="<",G17,G18))) -> 0 | N17: =IF(OR(H17="",H18=""),"Enter NOAEC & LOAEC in Column H", (GEOMEAN(H17:H18))) -> 4.6904158 | O17: MATC | BC17: Callinectes sapidus
H18: 11 | I18: LOAEC | K18: =IFERROR(IF(OR(H17="",H18=""),"Check NOAEC and LOAEC Data Entry",GEOMEAN(H17:H18)),"Check NOAEC and LOAEC Data Entry") -> 4.6904158 | L18: MATC | BC18: Carcinus maenas
B19: Crustacean Endpoints | C19: Acute (µg a.i./L) | D19: Americamysis bahia | G19: > | H19: 5 | I19: LC50 | J19: =IF(G19="","",G19) -> > | K19: =IF((LEN(TRIM(H19))=0),"--",H19) -> 5 | L19: LC50 | M19: =G19 -> > | N19: =IF((LEN(TRIM(H19))=0),"Enter LC50 in Column H",H19*0.5) -> 2.5 | O19: 0.5 * LC50 or HC05 | Q19: 5 | R19: LC50 or HC25 | BC19: Centroptilum triangulifer
C20: Chronic (µg a.i./L) | D20: Americamysis bahia | H20: 10 | I20: NOAEC | J20: =IF(G20="","",G20) | K20: =IF((LEN(TRIM(H20))=0),"--",H20) -> 10 | L20: NOAEC | M20: =IF(AND(G20="=",G21="="),G20,(IF(G20="<",G20,G21))) -> 0 | N20: =IF(OR(H20="",H21=""),"Enter NOAEC & LOAEC in Column H", (GEOMEAN(H20:H21))) -> 14.142136 | O20: MATC | BC20: Chimarra atterima
H21: 20 | I21: LOAEC | K21: =IFERROR(IF(OR(H20="",H21=""),"Check NOAEC and LOAEC Data Entry",GEOMEAN(H20:H21)),"Check NOAEC and LOAEC Data Entry") -> 14.142136 | L21: MATC | BC21: Chironomous riparius
B22: Insect Endpoints | C22: Acute (µg a.i./L) | D22: None Available | G22: = | H22: 0.002 | I22: LC50 | J22: =IF(G22="","",G22) -> = | K22: =IF((LEN(TRIM(H22))=0),"--",H22) -> 0.002 | L22: LC50 | M22: =G22 -> = | N22: =IF((LEN(TRIM(H22))=0),"Enter LC50 in Column H",H22*0.5) -> 0.001 | O22: 0.5 * LC50 or HC05 | Q22: 0.002 | R22: LC50 or HC25 | BC22: Chironomus tentans
C23: Chronic (µg a.i./L) | D23: None Available | H23: 0.01 | I23: NOAEC | J23: =IF(G23="","",G23) | K23: =IF((LEN(TRIM(H23))=0),"--",H23) -> 0.01 | L23: NOAEC | M23: =IF(AND(G23="=",G24="="),G23,(IF(G23="<",G23,G24))) -> 0 | N23: =IF(OR(H23="",H24=""),"Enter NOAEC & LOAEC in Column H", (GEOMEAN(H23:H24))) -> 0.014142136 | O23: MATC | BC23: Chironomus dilutus
H24: 0.02 | I24: LOAEC | K24: =IFERROR(IF(OR(H23="",H24=""),"Check NOAEC and LOAEC Data Entry",GEOMEAN(H23:H24)),"Check NOAEC and LOAEC Data Entry") -> 0.014142136 | L24: MATC | BC24: Chironomus kiinensis
B25: Mollusk Endpoints | C25: Acute (µg a.i./L) | D25: Mercenaria mercenaria | G25: > | H25: 9 | I25: LC50 | J25: =IF(G25="","",G25) -> > | K25: =IF((LEN(TRIM(H25))=0),"--",H25) -> 9 | L25: LC50 | M25: =G25 -> > | N25: =IF((LEN(TRIM(H25))=0),"Enter LC50 in Column H",H25*0.5) -> 4.5 | O25: 0.5 * LC50 or HC05 | Q25: 9 | R25: LC50 or HC25 | BC25: Chironomus riparius
C26: Chronic (µg a.i./L) | D26: None Available | H26: 10 | I26: NOAEC | J26: =IF(G26="","",G26) | K26: =IF((LEN(TRIM(H26))=0),"--",H26) -> 10 | L26: NOAEC | M26: =IF(AND(G26="=",G27="="),G26,(IF(G26="<",G26,G27))) -> 0 | N26: =IF(OR(H26="",H27=""),"Enter NOAEC & LOAEC in Column H", (GEOMEAN(H26:H27))) -> 14.142136 | O26: MATC | BC26: Crangon septemspinosa
H27: 20 | I27: LOAEC | K27: =IFERROR(IF(OR(H26="",H27=""),"Check NOAEC and LOAEC Data Entry",GEOMEAN(H26:H27)),"Check NOAEC and LOAEC Data Entry") -> 14.142136 | L27: MATC | BC27: Crassostrea gigas
B28: Benthic Invertebrates | C28: Chronic Freshwater Amphipod (µg a.i./kg-OC) | D28: Hyalla azteca | H28: 1000 | I28: NOAEC | J28: =IF(G28="","",G28) | K28: =IF((LEN(TRIM(H28))=0),"--",H28) -> 1000 | L28: NOAEC | M28: =IF(AND(G28="=",G29="="),G28,(IF(G28="<",G28,G29))) -> 0 | N28: =IF(OR(H28="",H29=""),"Enter NOAEC & LOAEC in Column H", (GEOMEAN(H28:H29))) -> 1414.2136 | O28: MATC | BC28: Crassostrea virginica
H29: 2000 | I29: LOAEC | K29: =IFERROR(IF(OR(H28="",H29=""),"Check NOAEC and LOAEC Data Entry",GEOMEAN(H28:H29)),"Check NOAEC and LOAEC Data Entry") -> 1414.2136 | L29: MATC | BC29: Daphnia magna
C30: Chronic Freshwater Amphipod (µg a.i./L pore water) | D30: Hyalla azteca | G30: = | H30: 2 | I30: NOAEC | J30: =IF(G30="","",G30) -> = | K30: =IF((LEN(TRIM(H30))=0),"--",H30) -> 2 | L30: NOAEC | M30: =IF(AND(G30="=",G31="="),G30,(IF(G30="<",G30,G31))) -> = | N30: =IF(OR(H30="",H31=""),"Enter NOAEC & LOAEC in Column H", (GEOMEAN(H30:H31))) -> 6.4807407 | O30: MATC | BC30: Eisenia fetida
G31: = | H31: 21 | I31: LOAEC | K31: =IFERROR(IF(OR(H30="",H31=""),"Check NOAEC and LOAEC Data Entry",GEOMEAN(H30:H31)),"Check NOAEC and LOAEC Data Entry") -> 6.4807407 | L31: MATC | BC31: Folsomia candida
C32: Chronic Freshwater Midge (µg a.i./kg-OC) | D32: Chironomus dilutus | H32: 5000 | I32: NOAEC | J32: =IF(G32="","",G32) | K32: =IF((LEN(TRIM(H32))=0),"--",H32) -> 5000 | L32: NOAEC | M32: =IF(AND(G32="=",G33="="),G32,(IF(G32="<",G32,G33))) -> 0 | N32: =IF(OR(H32="",H33=""),"Enter NOAEC & LOAEC in Column H", (GEOMEAN(H32:H33))) -> 5477.2256 | O32: MATC | BC32: Crassostrea virginica
H33: 6000 | I33: LOAEC | K33: =IFERROR(IF(OR(H32="",H33=""),"Check NOAEC and LOAEC Data Entry",GEOMEAN(H32:H33)),"Check NOAEC and LOAEC Data Entry") -> 5477.2256 | L33: MATC | BC33: Daphnia magna
C34: Chronic Freshwater Midge (µg a.i./L pore water) | D34: Chironomus dilutus | G34: = | H34: 2 | I34: NOAEC | J34: =IF(G34="","",G34) -> = | K34: =IF((LEN(TRIM(H34))=0),"--",H34) -> 2 | L34: NOAEC | M34: =IF(AND(G34="=",G35="="),G34,(IF(G34="<",G34,G35))) -> = | N34: =IF(OR(H34="",H35=""),"Enter NOAEC & LOAEC in Column H", (GEOMEAN(H34:H35))) -> 6.4807407 | O34: MATC | BC34: Eisenia fetida
G35: = | H35: 21 | I35: LOAEC | K35: =IFERROR(IF(OR(H34="",H35=""),"Check NOAEC and LOAEC Data Entry",GEOMEAN(H34:H35)),"Check NOAEC and LOAEC Data Entry") -> 6.4807407 | L35: MATC | BC35: Folsomia candida
C36: Chronic Estuarine/Marine (µg a.i./kg-OC) | D36: Leptocheirus plumulosus | H36: 5500 | I36: NOAEC | J36: =IF(G36="","",G36) | K36: =IF((LEN(TRIM(H36))=0),"--",H36) -> 5500 | L36: NOAEC | M36: =IF(AND(G36="=",G37="="),G36,(IF(G36="<",G36,G37))) -> 0 | N36: =IF(OR(H36="",H37=""),"Enter NOAEC & LOAEC in Column H", (GEOMEAN(H36:H37))) -> 5744.5626 | O36: MATC | BC36: Gammarus pseudolimnaeus
H37: 6000 | I37: LOAEC | K37: =IFERROR(IF(OR(H36="",H37=""),"Check NOAEC and LOAEC Data Entry",GEOMEAN(H36:H37)),"Check NOAEC and LOAEC Data Entry") -> 5744.5626 | L37: MATC | BC37: Gammarus pulex
C38: Chronic Estuarine/Marine (µg a.i./L pore water) | D38: Leptocheirus plumulosus | H38: 21 | I38: NOAEC | J38: =IF(G38="","",G38) | K38: =IF((LEN(TRIM(H38))=0),"--",H38) -> 21 | L38: NOAEC | M38: =IF(AND(G38="=",G39="="),G38,(IF(G38="<",G38,G39))) -> 0 | N38: =IF(OR(H38="",H39=""),"Enter NOAEC & LOAEC in Column H", (GEOMEAN(H38:H39))) -> 30.397368 | O38: MATC | BC38: Hyalella azteca
H39: 44 | I39: LOAEC | K39: =IFERROR(GEOMEAN(H39:H40),"Check NOAEC and LOAEC Data Entry") -> 3.8105118 | L39: MATC | BC39: Laodelphax striatellus
A40: Aquatic Plants | C40: Vascular (µg a.i./L) | H40: 0.33 | I40: EC50 | K40: =IF((LEN(TRIM(H41))=0),"--",H41) -> 0.1 | L40: NOAEC/IC05 | N40: 0.33 | O40: Non-vascular EC50 or HC05 | Q40: 0.33 | R40: EC50 or HC25 | BC40: Leptocheirus plumulosus
...

Sheet Endpoints for Terrestrial
G1: Blue Shading = Manual entry; Green Shading = Automated; ONLY INPUT DEFINITIVE VALUES
C2: Endpoint Type (Units) | D2: Test species (Must USE DROPDOWN where Blue) | E2: Test Species Notes: | F2: MRID | G2: Non-Listed Taxa | J2: Listed Individuals | M2: Listed Populations | P2: Community Level (as needed) | S2: Additional Comments:
G3: Operator = />/< | H3: Value | I3: Type | J3: Operator = />/< | K3: Value | L3: Type | M3: Operator = />/< | N3: Value | O3: Type | P3: Operator = />/< | Q3: Value | R3: Type | AZ3: LOOKUP VALUES
A4: Terrestrial Vertebrates | B4: Birds | C4: Acute Oral (mg a.i./kg-bw) | D4: Northern bobwhite (Colinus virginianus) | G4: = | H4: 125 | I4: LD50 | J4: =G4 -> = | K4: =IF((LEN(TRIM(H4))=0),"--",H4) -> 125 | L4: LD50 | M4: =G4 -> = | N4: =IF((LEN(TRIM(H4))=0),"Enter LC50 in Column H",H4*0.5) -> 62.5 | O4: 0.5 * LD50 or HC05 | Q4: 125 | R4: HC25 or surrogate | AZ4: Operators | BB4: Test Species > | BC4: None Available
C5: Subacute Dietary (mg a.i./kg diet) | D5: Mallard duck (Anas platyrhynchos) | G5: < | H5: 56 | I5: LC50 | J5: =G5 -> < | K5: =IF((LEN(TRIM(H5))=0),"--",H5) -> 56 | L5: LC50 | M5: =G5 -> < | N5: =IF((LEN(TRIM(H5))=0),"Enter LC50 in Column H",H5*0.5) -> 28 | O5: 0.5 * LC50 or HC05 | AZ5: = | BC5: Other
C6: Chronic Reproduction (mg a.i./kg diet) | D6: Northern bobwhite (Colinus virginianus) | G6: = | H6: 2 | I6: NOAEC | J6: =G6 -> = | K6: =IF((LEN(TRIM(H6))=0),"--",H6) -> 2 | L6: NOAEC | M6: =IF(AND(G6="=",G7="="),G6,(IF(G6="<",G6,G7))) -> > | N6: =IF(OR(H6="",H7=""),"Enter NOAEC & LOAEC in Column H", (GEOMEAN(H6:H7))) -> 10 | O6: MATC | AZ6: > | BC6: Multiple - SSD
G7: > | H7: 50 | I7: LOAEC | K7: =IF(OR(H6="",H7=""),"Enter NOAEC & LOAEC in Column H", (GEOMEAN(H6:H7))) -> 10 | L7: MATC | AZ7: < | BC7: Anodonta sp.
B8: Mammals | C8: Rat-Acute Oral (mg a.i./kg-bw) | D8: Norway rat (Rattus norvegicus) | G8: = | H8: 450 | I8: LD50 | J8: =G8 -> = | K8: =IF((LEN(TRIM(H8))=0),"--",H8) -> 450 | L8: LD50 | M8: =G8 -> = | N8: =IF((LEN(TRIM(H8))=0),"Enter LC50 in Column H",H8*0.5) -> 225 | O8: 0.5 * LD50 or HC05 | Q8: 450 | R8: HC25 or surrogate | BC8: Uca pugilator
C9: Rat-Chronic (Dose) (mg a.i./kg-bw) | D9: Norway rat (Rattus norvegicus) | G9: < | H9: 8 | I9: NOAEL | J9: =G9 -> < | K9: =IF((LEN(TRIM(H9))=0),"--",H9) -> 8 | L9: NOAEL | M9: =IF(AND(G9="=",G10="="),G9,(IF(G9="<",G9,G10))) -> < | N9: =IF(OR(H9="",H10=""),"Enter NOAEL & LOAEL in Column H", (GEOMEAN(H9:H10))) -> 24.494897 | O9: MATL | BC9: Aedes taeniorhynchus
G10: = | H10: 75 | I10: LOAEL | K10: =IF(OR(H9="",H10=""),"Enter NOAEC & LOAEC in Column H", (GEOMEAN(H9:H10))) -> 24.494897 | L10: MATL | BC10: Allolobophora tuberculata
C11: Rat-Chronic (Diet) (mg a.i./kg-diet) | D11: Norway rat (Rattus norvegicus) | G11: = | H11: 12 | I11: NOAEC | J11: =G11 -> = | K11: =IF((LEN(TRIM(H11))=0),"--",H11) -> 12 | L11: NOAEC | M11: =IF(AND(G11="=",G12="="),G11,(IF(G11="<",G11,G12))) -> = | N11: =IF(OR(H11="",H12=""),"Enter NOAEC & LOAEC in Column H", (GEOMEAN(H11:H12))) -> 24 | O11: MATC | BC11: Americamysis bahia
G12: = | H12: 48 | I12: LOAEC | K12: =IF(OR(H11="",H12=""),"Enter NOAEC & LOAEC in Column H", (GEOMEAN(H11:H12))) -> 24 | L12: MATC | BC12: Aphidius rhopalosiphi
B13: Amphibian (or Birds) | C13: Acute Oral (mg a.i./kg-bw) | D13: Northern bobwhite (Colinus virginianus) | G13: = | H13: 125 | I13: LD50 | J13: =G13 -> = | K13: =IF((LEN(TRIM(H13))=0),"--",H13) -> 125 | L13: LD50 | M13: =G13 -> = | N13: =IF((LEN(TRIM(H13))=0),"Enter LC50 in Column H",H13*0.5) -> 62.5 | O13: 0.5 * LD50 or HC05 | Q13: 125 | R13: HC25 or surrogate | BC13: Apis mellifera
C14: Subacute Dietary (mg a.i./kg diet) | D14: Mallard duck (Anas platyrhynchos) | G14: = | H14: 56 | I14: LC50 | J14: =G14 -> = | K14: =IF((LEN(TRIM(H14))=0),"--",H14) -> 56 | L14: LC50 | M14: =G14 -> = | N14: =IF((LEN(TRIM(H14))=0),"Enter LC50 in Column H",H14*0.5) -> 28 | O14: 0.5 * LC50 or HC05 | BC14: Bombus impatiens
C15: Chronic Reproduction (mg a.i./kg diet) | D15: Northern bobwhite (Colinus virginianus) | G15: = | H15: 2 | I15: NOAEC | J15: =G15 -> = | K15: =IF((LEN(TRIM(H15))=0),"--",H15) -> 2 | L15: NOAEC | M15: =IF(AND(G15="=",G16="="),G15,(IF(G15="<",G15,G16))) -> = | N15: =IF(OR(H15="",H16=""),"Enter NOAEC & LOAEC in Column H", (GEOMEAN(H15:H16))) -> 10 | O15: MATC | BC15: Bombus terrestris
G16: = | H16: 50 | I16: LOAEC | K16: =IF(OR(H15="",H16=""),"Enter NOAEC & LOAEC in Column H", (GEOMEAN(H15:H16))) -> 10 | L16: MATC | BC16: Brachionus calyciflorus
A17: Terrestrial Invertebrates | B17: Adult Bee | C17: Acute contact (ug a.i./bee) | G17: = | H17: 5 | I17: LD50 | J17: =G17 -> = | K17: =IF((LEN(TRIM(H17))=0),"--",H17) -> 5 | L17: LD50 | M17: =G17 -> = | N17: =IF((LEN(TRIM(H17))=0),"Enter LC50 in Column H",H17*0.4) -> 2 | O17: 0.4 * LD50 or HC05 | Q17: 5 | R17: HC25 or AAC LD50 | BC17: Callinectes sapidus
C18: Dose-Based Acute Oral (µg a.i./bee) | G18: > | H18: 10 | I18: LD50 | J18: =G18 -> > | K18: =IF((LEN(TRIM(H18))=0),"--",H18) -> 10 | L18: LD50 | M18: =G18 -> > | N18: =IF((LEN(TRIM(H18))=0),"Enter LC50 in Column H",H18*0.4) -> 4 | O18: 0.4 * LD50 or HC05 | Q18: 10 | R18: HC25 or surrogate | BC18: Carcinus maenas
C19: Dose-Based Chronic Oral (µg a.i./bee) | G19: = | H19: 8 | I19: NOAEL | J19: =G19 -> = | K19: =IF((LEN(TRIM(H19))=0),"--",H19) -> 8 | L19: NOAEL | M19: =IF(AND(G19="=",G20="="),G19,(IF(G19="<",G19,G20))) -> = | N19: =IF(OR(H19="",H20=""),"Enter NOAEL & LOAEL in Column H", (GEOMEAN(H19:H20))) -> 8.4852814 | O19: MATL | BC19: Centroptilum triangulifer
G20: = | H20: 9 | I20: LOAEL | K20: =IF(OR(H19="",H20=""),"Enter NOAEC & LOAEC in Column H", (GEOMEAN(H19:H20))) -> 8.4852814 | L20: MATL | BC20: Chimarra atterima
B21: Larval Bee | C21: Dose-based Acute Oral (µg a.i./larva) | G21: = | H21: 50 | I21: LD50 | J21: =G21 -> = | K21: =IF((LEN(TRIM(H21))=0),"--",H21) -> 50 | L21: LD50 | M21: =G21 -> = | N21: =IF((LEN(TRIM(H21))=0),"Enter LC50 in Column H",H21*0.4) -> 20 | O21: 0.4 * LD50 or HC05 | R21: LAO LC50 | BC21: Chironomous riparius
C22: Dose-based Chronic Oral (µg a.i./larva) | G22: = | H22: 1 | I22: NOAEL | J22: =G22 -> = | K22: =IF((LEN(TRIM(H22))=0),"--",H22) -> 1 | L22: NOAEL | M22: =IF(AND(G22="=",G23="="),G22,(IF(G22="<",G22,G23))) -> = | N22: =IF(OR(H22="",H23=""),"Enter NOAEL & LOAEL in Column H", (GEOMEAN(H22:H23))) -> 2.236068 | O22: MATL | BC22: Chironomus tentans
G23: = | H23: 5 | I23: LOAEL | K23: =IF(OR(H22="",H23=""),"Enter NOAEC & LOAEC in Column H", (GEOMEAN(H22:H23))) -> 2.236068 | L23: MATL | BC23: Chironomus dilutus
B24: Adult Invertebrate (Non-Specific) [usually honey bee dietary endpoints] | C24: Acute Oral (mg a.i./kg-diet) | G24: = | H24: 2 | I24: LC50 | J24: =G24 -> = | K24: =IF((LEN(TRIM(H24))=0),"--",H24) -> 2 | L24: LC50 | M24: =G24 -> = | N24: =IF((LEN(TRIM(H24))=0),"Enter LC50 in Column H",H24*0.4) -> 0.8 | O24: 0.4 * LC50 or HC05 | Q24: 2 | R24: HC25 or surrogate | BC24: Chironomus kiinensis
C25: Chronic Oral (mg a.i./kg-diet) | G25: = | H25: 0.4 | I25: NOAEC | J25: =G25 -> = | K25: =IF((LEN(TRIM(H25))=0),"--",H25) -> 0.4 | L25: NOAEC | M25: =IF(AND(G25="=",G26="="),G25,(IF(G25="<",G25,G26))) -> = | N25: =IF(OR(H25="",H26=""),"Enter NOAEC & LOAEC in Column H", (GEOMEAN(H25:H26))) -> 0.63245553 | O25: MATC | BC25: Chironomus riparius
G26: = | H26: 1 | I26: LOAEC | K26: =IF(OR(H25="",H26=""),"Enter NOAEC & LOAEC in Column H", (GEOMEAN(H25:H26))) -> 0.63245553 | L26: MATC | BC26: Crangon septemspinosa
B27: Larval Invertebrate (Non-Specific) [among most sensitive dietary endpoint] | C27: Acute Oral (mg a.i./kg-diet) | G27: = | H27: 12 | I27: LC50 | J27: =G27 -> = | K27: =IF((LEN(TRIM(H27))=0),"--",H27) -> 12 | L27: LC50 | M27: =G27 -> = | N27: =IF((LEN(TRIM(H27))=0),"Enter LC50 in Column H",H27*0.4) -> 4.8 | O27: 0.4 * LC50 or HC05 | R27: LAO LC50 | BC27: Crassostrea gigas
C28: Chronic (mg a.i./kg-diet) | G28: = | H28: 2 | I28: NOAEC | J28: =G28 -> = | K28: =IF((LEN(TRIM(H28))=0),"--",H28) -> 2 | L28: NOAEC | M28: =IF(AND(G28="=",G29="="),G28,(IF(G28="<",G28,G29))) -> = | N28: =IF(OR(H28="",H29=""),"Enter NOAEC & LOAEC in Column H", (GEOMEAN(H28:H29))) -> 3.4641016 | O28: MATC | BC28: Crassostrea virginica
G29: = | H29: 6 | I29: LOAEC | K29: =IF(OR(H28="",H29=""),"Enter NOAEC & LOAEC in Column H", (GEOMEAN(H28:H29))) -> 3.4641016 | L29: MATC | BC29: Daphnia magna
B30: Adult Bumble Bee | C30: Acute Oral (µg a.i./bee) | G30: = | H30: 20 | I30: LC50 | J30: =G30 -> = | K30: =IF((LEN(TRIM(H30))=0),"--",H30) -> 20 | L30: LC50 | M30: =G30 -> = | N30: =IF((LEN(TRIM(H30))=0),"Enter LC50 in Column H",H30*0.4) -> 8 | O30: 0.4 * LC50 or HC05 | Q30: 20 | R30: HC25 or surrogate | BC30: Eisenia fetida
C31: Chronic Oral (µg a.i./bee) | G31: = | H31: 5 | I31: NOAEC | J31: =G31 -> = | K31: =IF((LEN(TRIM(H31))=0),"--",H31) -> 5 | L31: NOAEC | M31: =IF(AND(G31="=",G32="="),G31,(IF(G31="<",G31,G32))) -> = | N31: =IF(OR(H31="",H32=""),"Enter NOAEC & LOAEC in Column H", (GEOMEAN(H31:H32))) -> 7.0710678 | O31: MATC | BC31: Folsomia candida
G32: = | H32: 10 | I32: LOAEC | K32: =IF(OR(H31="",H32=""),"Enter NOAEC & LOAEC in Column H", (GEOMEAN(H31:H32))) -> 7.0710678 | L32: MATC | BC32: Gammarus pseudolimnaeus
B33: Butterflies (adult) | C33: Acute Oral (mg a.i./kg-diet) | G33: = | H33: 20 | I33: LC50 | J33: =G33 -> = | K33: =IF((LEN(TRIM(H33))=0),"--",H33) -> 20 | L33: LC50 | M33: =G33 -> = | N33: =IF((LEN(TRIM(H33))=0),"Enter LC50 in Column H",H33*0.4) -> 8 | O33: 0.4 * LC50 or HC05 | R33: HC25 or surrogate | BC33: Gammarus pulex
C34: Chronic Oral (mg a.i./kg-diet) | G34: = | H34: 5 | I34: NOAEC | J34: =G34 -> = | K34: =IF((LEN(TRIM(H34))=0),"--",H34) -> 5 | L34: NOAEC | M34: =IF(AND(G34="=",G35="="),G34,(IF(G34="<",G34,G35))) -> = | N34: =IF(OR(H34="",H35=""),"Enter NOAEC & LOAEC in Column H", (GEOMEAN(H34:H35))) -> 7.0710678 | O34: MATC | BC34: Hyalella azteca
G35: = | H35: 10 | I35: LOAEC | K35: =IF(OR(H34="",H35=""),"Enter NOAEC & LOAEC in Column H", (GEOMEAN(H34:H35))) -> 7.0710678 | L35: MATC | BC35: Laodelphax striatellus
B36: Beetles (adult) | C36: Acute Oral (mg a.i./kg-diet) | G36: = | H36: 20 | I36: LC50 | J36: =G36 -> = | K36: =IF((LEN(TRIM(H36))=0),"--",H36) -> 20 | L36: LC50 | M36: =G36 -> = | N36: =IF((LEN(TRIM(H36))=0),"Enter LC50 in Column H",H36*0.4) -> 8 | O36: 0.4 * LC50 or HC05 | R36: HC25 or surrogate | BC36: Leptocheirus plumulosus
C37: Chronic Oral (mg a.i./kg-diet) | G37: = | H37: 5 | I37: NOAEC | J37: =G37 -> = | K37: =IF((LEN(TRIM(H37))=0),"--",H37) -> 5 | L37: NOAEC | M37: =IF(AND(G37="=",G38="="),G37,(IF(G37="<",G37,G38))) -> = | N37: =IF(OR(H37="",H38=""),"Enter NOAEC & LOAEC in Column H", (GEOMEAN(H37:H38))) -> 7.0710678 | O37: MATC | BC37: Locusta migratoria
G38: = | H38: 10 | I38: LOAEC | K38: =IF(OR(H37="",H38=""),"Enter NOAEC & LOAEC in Column H", (GEOMEAN(H37:H38))) -> 7.0710678 | L38: MATC | BC38: Lumbriculus variegatus
B39: Soil Exposure | C39: Acute (mg a.i./kg dw soil) | G39: = | H39: 20 | I39: LC50 | J39: =G39 -> = | K39: =IF((LEN(TRIM(H39))=0),"--",H39) -> 20 | L39: LC50 | M39: =G39 -> = | N39: =IF((LEN(TRIM(H39))=0),"Enter LC50 in Column H",H39*0.4) -> 8 | O39: 0.4 * LC50 or HC05 | R39: HC25 or surrogate | BC39: Lygus lineolaris
C40: Chronic (mg a.i./kg dw soil) | G40: = | H40: 5 | I40: NOAEC | J40: =G40 -> = | K40: =IF((LEN(TRIM(H40))=0),"--",H40) -> 5 | L40: NOAEC | M40: =IF(AND(G40="=",G41="="),G40,(IF(G40="<",G40,G41))) -> = | N40: =IF(OR(H40="",H41=""),"Enter NOAEC & LOAEC in Column H", (GEOMEAN(H40:H41))) -> 7.0710678 | O40: MATC | BC40: Mercenaria mercenaria
...

Sheet USE SUMMARY TABLE
B1: Enter all uses to be modeled (fill in ALL yellow relevant cells)
M2: For PWC Inputs | Q2: Not required for all uses
A3: Use Site (Automatically Filled) | B3: Use Site (Begin to enter name and select from dropdown) | C3: Maximum Single Application Rate (lbs a.i./A) from Label (enter numeric value) | D3: Maximum Number of Applications at Max Application Rate (enter numeric value) | E3: Modeled Single Application Rates (separate multiple applications with commas, keep in order of appliciaton) | F3: Annual Maximum Application Rate (lbs a.i./A) from Label | G3: Application Type (App method in PWC) (Select from Dropdown) | H3: Spray Drift Application Method(s) (Select from dropdown) | I3: Aerial Spray Drift Assumption (Select from dropdown; default assumption Aerial_Medium) | J3: Ground Spray Drift Assumption (Select from dropdown; default assumption Ground_VF-F HB) | K3: Airblast (Select from dropdown; default assumption Airblast Sparse) | L3: Minimum Retreatment Interval (days) | M3: Relative Application Timing (Select from dropdown) | N3: For PWC Modeling: Variable days of Application (enter values separated by commas) | O3: For Terrestrial Modeling: Variable days of Application (enter values separated by commas) | P3: Foliar vs Soil uptake assumption for BeeREX (Select from dropdown; default is Foliar) | Q3: Seed Treatment Rate for Direct Feeding and Uptake Rate Assessment (mg a.i./seed) | R3: Aquatic Target Concentration ug a.i./L (only applicable when indicated in Column T) | S3: Geographic Definition (Select from Dropdown) | T3: PWC Scenario Name (Automatically Matched) | U3: UDL (Automatically Matched) | V3: Notes
A4: 1 | B4: Corn | C4: 0.75 | D4: 1 | E4: 0.75 | F4: 0.75 | G4: Spray, Granular | H4: Ground | I4: Aerial_Coarse | J4: Ground_F-MC_HB | K4: Airblast_Sparse | M4: Pre-emergence | N4: -14 | P4: Foliar Spray | S4: L48 | T4: =IFERROR(VLOOKUP($B4,'Lookup Tables For Tool'!$D:$F,3,FALSE),"Enter Use Site") -> Corn | U4: =IFERROR(VLOOKUP($B4,'Lookup Tables For Tool'!$D:$F,2,FALSE),"Enter Use Site") -> Corn
A5: =A4+1 -> 2 | B5: Soybean (Glycine max) | C5: 1.125 | D5: 3 | E5: 1.125,1,0.875 | F5: 3 | G5: Spray | H5: Ground | I5: Aerial_Fine_50 | J5: Ground_VF-F_HB | L5: 7 | M5: Post-emergence | N5: 0,7,14 | O5: 1,7,14 | P5: Foliar Spray | S5: L48, NL48 | T5: =IFERROR(VLOOKUP($B5,'Lookup Tables For Tool'!$D:$F,3,FALSE),"Enter Use Site") -> Soybean | U5: =IFERROR(VLOOKUP($B5,'Lookup Tables For Tool'!$D:$F,2,FALSE),"Enter Use Site") -> Soybeans
A6: =A5+1 -> 3 | B6: Almond | C6: 1 | D6: 1 | E6: 1 | F6: 1 | G6: Spray | H6: Ground, Aerial | I6: Aerial_Medium | J6: Ground_VF-F_LB | K6: Airblast_Sparse | M6: Pre-emergence | N6: 1 | P6: Soil Spray | S6: L48, NL48 | T6: =IFERROR(VLOOKUP($B6,'Lookup Tables For Tool'!$D:$F,3,FALSE),"Enter Use Site") -> Orchard deciduous | U6: =IFERROR(VLOOKUP($B6,'Lookup Tables For Tool'!$D:$F,2,FALSE),"Enter Use Site") -> Other Orchards
A7: =A6+1 -> 4 | B7: Citrus hybrids, Citrus spp. Eremocitrus spp., Fortunella spp., Microcitrus spp., and Poncirus spp | C7: 1 | D7: 2 | E7: 0.5,1 | F7: 1.5 | G7: Spray | H7: Ground | I7: Aerial_Very_Coarse | J7: Ground_F-MC_LB | L7: 14 | M7: Pre-emergence | N7: -28,-14 | O7: 1,14 | P7: Foliar Spray | S7: L48 | T7: =IFERROR(VLOOKUP($B7,'Lookup Tables For Tool'!$D:$F,3,FALSE),"Enter Use Site") -> Orchard evergreen | U7: =IFERROR(VLOOKUP($B7,'Lookup Tables For Tool'!$D:$F,2,FALSE),"Enter Use Site") -> Citrus
A8: =A7+1 -> 5 | B8: Blackberry | C8: 1 | D8: 1 | E8: 1 | F8: 1 | G8: Spray | H8: Ground | J8: Ground_F-MC_HB | M8: Post-emergence | N8: 1 | P8: Foliar Spray | S8: L48 | T8: =IFERROR(VLOOKUP($B8,'Lookup Tables For Tool'!$D:$F,3,FALSE),"Enter Use Site") -> Small fruit trellised | U8: =IFERROR(VLOOKUP($B8,'Lookup Tables For Tool'!$D:$F,2,FALSE),"Enter Use Site") -> Vegetables and Ground Fruit
A9: =A8+1 -> 6 | B9: Broccoli | C9: 0.5 | D9: 1 | E9: 0.5 | F9: 0.5 | G9: Spray | H9: Ground | J9: Ground_F-MC_HB | M9: Pre-emergence | N9: -14 | P9: Foliar Spray | S9: L48 | T9: =IFERROR(VLOOKUP($B9,'Lookup Tables For Tool'!$D:$F,3,FALSE),"Enter Use Site") -> Vegetable fresh or processing market | U9: =IFERROR(VLOOKUP($B9,'Lookup Tables For Tool'!$D:$F,2,FALSE),"Enter Use Site") -> Vegetables and Ground Fruit
A10: =A9+1 -> 7 | B10: Garlic, Bulb | C10: 0.25 | D10: 1 | E10: 0.25 | F10: 0.25 | G10: Granular | H10: Ground | M10: Pre-emergence | N10: -14 | P10: soil/granular | S10: NL48 | T10: =IFERROR(VLOOKUP($B10,'Lookup Tables For Tool'!$D:$F,3,FALSE),"Enter Use Site") -> Vegetable fresh or processing market | U10: =IFERROR(VLOOKUP($B10,'Lookup Tables For Tool'!$D:$F,2,FALSE),"Enter Use Site") -> Vegetables and Ground Fruit
A11: =A10+1 -> 8 | B11: Wheat, Triticum spp | C11: 1 | D11: 1 | E11: 1 | F11: 1 | G11: Seed | M11: Pre-emergence | N11: -14 | P11: seed | Q11: 1.2 | S11: L48, NL48 | T11: =IFERROR(VLOOKUP($B11,'Lookup Tables For Tool'!$D:$F,3,FALSE),"Enter Use Site") -> Wheat spring | U11: =IFERROR(VLOOKUP($B11,'Lookup Tables For Tool'!$D:$F,2,FALSE),"Enter Use Site") -> Spring wheat
A12: =A11+1 -> 9 | B12: Clover | C12: 1 | D12: 2 | E12: 1,1 | F12: 2 | G12: Spray | I12: Aerial_Coarse | J12: Ground_F-MC_HB | L12: 35 | M12: Post-emergence | N12: 0,35 | O12: 1,34 | P12: Foliar Spray | S12: L48, NL48 | T12: =IFERROR(VLOOKUP($B12,'Lookup Tables For Tool'!$D:$F,3,FALSE),"Enter Use Site") -> Hay all | U12: =IFERROR(VLOOKUP($B12,'Lookup Tables For Tool'!$D:$F,2,FALSE),"Enter Use Site") -> Other crops
A13: =A12+1 -> 10 | B13: Apple | C13: 2 | D13: 2 | E13: 2,2 | F13: 4 | G13: Spray | I13: Aerial_Medium | J13: Ground_F-MC_HB | K13: Airblast_Sparse | L13: 10 | M13: Post-emergence | N13: 0,10 | O13: 1,11 | P13: Foliar Spray | S13: L48 | T13: =IFERROR(VLOOKUP($B13,'Lookup Tables For Tool'!$D:$F,3,FALSE),"Enter Use Site") -> Orchard deciduous | U13: =IFERROR(VLOOKUP($B13,'Lookup Tables For Tool'!$D:$F,2,FALSE),"Enter Use Site") -> Other Orchards
A14: =A13+1 -> 11 | B14: Grass, Pasture | C14: 1 | D14: 1 | E14: 1 | F14: 1 | G14: Spray | I14: Aerial_Medium | J14: Ground_F-MC_HB | M14: Post-emergence | N14: 3/1 | P14: Foliar Spray | S14: L48 | T14: =IFERROR(VLOOKUP($B14,'Lookup Tables For Tool'!$D:$F,3,FALSE),"Enter Use Site") -> Pasture or forage | U14: =IFERROR(VLOOKUP($B14,'Lookup Tables For Tool'!$D:$F,2,FALSE),"Enter Use Site") -> Range
A15: =A14+1 -> 12 | B15: AQUATICS: Water/Fluids/Waste Materials and Systems (Not intended for direct human consumption or food contact) | R15: 2.5 | T15: =IFERROR(VLOOKUP($B15,'Lookup Tables For Tool'!$D:$F,3,FALSE),"Enter Use Site") -> Target Concentration | U15: =IFERROR(VLOOKUP($B15,'Lookup Tables For Tool'!$D:$F,2,FALSE),"Enter Use Site") -> non-cultivated
A16: =A15+1 -> 13 | T16: =IFERROR(VLOOKUP($B16,'Lookup Tables For Tool'!$D:$F,3,FALSE),"Enter Use Site") -> Enter Use Site | U16: =IFERROR(VLOOKUP($B16,'Lookup Tables For Tool'!$D:$F,2,FALSE),"Enter Use Site") -> Enter Use Site
A17: =A16+1 -> 14 | T17: =IFERROR(VLOOKUP($B17,'Lookup Tables For Tool'!$D:$F,3,FALSE),"Enter Use Site") -> Enter Use Site | U17: =IFERROR(VLOOKUP($B17,'Lookup Tables For Tool'!$D:$F,2,FALSE),"Enter Use Site") -> Enter Use Site
A18: =A17+1 -> 15 | T18: =IFERROR(VLOOKUP($B18,'Lookup Tables For Tool'!$D:$F,3,FALSE),"Enter Use Site") -> Enter Use Site | U18: =IFERROR(VLOOKUP($B18,'Lookup Tables For Tool'!$D:$F,2,FALSE),"Enter Use Site") -> Enter Use Site
A19: =A18+1 -> 16 | T19: =IFERROR(VLOOKUP($B19,'Lookup Tables For Tool'!$D:$F,3,FALSE),"Enter Use Site") -> Enter Use Site | U19: =IFERROR(VLOOKUP($B19,'Lookup Tables For Tool'!$D:$F,2,FALSE),"Enter Use Site") -> Enter Use Site
A20: =A19+1 -> 17 | T20: =IFERROR(VLOOKUP($B20,'Lookup Tables For Tool'!$D:$F,3,FALSE),"Enter Use Site") -> Enter Use Site | U20: =IFERROR(VLOOKUP($B20,'Lookup Tables For Tool'!$D:$F,2,FALSE),"Enter Use Site") -> Enter Use Site
A21: =A20+1 -> 18 | T21: =IFERROR(VLOOKUP($B21,'Lookup Tables For Tool'!$D:$F,3,FALSE),"Enter Use Site") -> Enter Use Site | U21: =IFERROR(VLOOKUP($B21,'Lookup Tables For Tool'!$D:$F,2,FALSE),"Enter Use Site") -> Enter Use Site
A22: =A21+1 -> 19 | T22: =IFERROR(VLOOKUP($B22,'Lookup Tables For Tool'!$D:$F,3,FALSE),"Enter Use Site") -> Enter Use Site | U22: =IFERROR(VLOOKUP($B22,'Lookup Tables For Tool'!$D:$F,2,FALSE),"Enter Use Site") -> Enter Use Site
A23: =A22+1 -> 20 | T23: =IFERROR(VLOOKUP($B23,'Lookup Tables For Tool'!$D:$F,3,FALSE),"Enter Use Site") -> Enter Use Site | U23: =IFERROR(VLOOKUP($B23,'Lookup Tables For Tool'!$D:$F,2,FALSE),"Enter Use Site") -> Enter Use Site
A24: =A23+1 -> 21 | T24: =IFERROR(VLOOKUP($B24,'Lookup Tables For Tool'!$D:$F,3,FALSE),"Enter Use Site") -> Enter Use Site | U24: =IFERROR(VLOOKUP($B24,'Lookup Tables For Tool'!$D:$F,2,FALSE),"Enter Use Site") -> Enter Use Site
A25: =A24+1 -> 22 | T25: =IFERROR(VLOOKUP($B25,'Lookup Tables For Tool'!$D:$F,3,FALSE),"Enter Use Site") -> Enter Use Site | U25: =IFERROR(VLOOKUP($B25,'Lookup Tables For Tool'!$D:$F,2,FALSE),"Enter Use Site") -> Enter Use Site
A26: =A25+1 -> 23 | T26: =IFERROR(VLOOKUP($B26,'Lookup Tables For Tool'!$D:$F,3,FALSE),"Enter Use Site") -> Enter Use Site | U26: =IFERROR(VLOOKUP($B26,'Lookup Tables For Tool'!$D:$F,2,FALSE),"Enter Use Site") -> Enter Use Site
A27: =A26+1 -> 24 | T27: =IFERROR(VLOOKUP($B27,'Lookup Tables For Tool'!$D:$F,3,FALSE),"Enter Use Site") -> Enter Use Site | U27: =IFERROR(VLOOKUP($B27,'Lookup Tables For Tool'!$D:$F,2,FALSE),"Enter Use Site") -> Enter Use Site
... A54: =A53+1 -> 51 | T54: =IFERROR(VLOOKUP($B54,'Lookup Tables For Tool'!$D:$F,3,FALSE),"Enter Use Site") -> Enter Use Site | U54: =IFERROR(VLOOKUP($B54,'Lookup Tables For Tool'!$D:$F,2,FALSE),"Enter Use Site") -> Enter Use Site
B55: TO ADD MORE USES: Copy last row and insert it into this row.
B56: Blank rows are ok to leave in the table above, just do not skip rows beween use sites

Sheet Physiochemical Data Entry
A1: Information for PWC Runs | B1: ENTER Values into all purple cells (no blanks unless stated)
A2: Parameter | B2: Koc (provide if used in PWC) | C2: Kd (provide if used in PWC) | D2: Effective KOC (Entered KOC in B3, or entered Kd/foc)
A3: Sorption (ml/g) | C3: 0.52 | D3: =IF(B3="",C3/B24,B3) -> 13
A4: Water Column Halflife (day) | B4: 45
A5: Water Reference Temperature (°C) | B5: 25
A6: Benthic Halflife (day) | B6: 321 | C6: DO NOT USE "0"
A7: Benthic Reference Temperature (°C) | B7: 25
A8: Aqueous Photolysis Halflife (day) | B8: 12.98 | C8: DO NOT USE "0"
A9: Photolysis Reference Latitude (°N) | B9: 40
A10: Hydrolysis Halflife (day) | B10: 50000 | C10: DO NOT USE "0"
A11: Soil Halflife (day) | B11: 6.92 | C11: DO NOT USE "0"
A12: Soil Reference Temperature (°C) | B12: 25
A13: Foliar Halflife (day) | B13: 50000 | C13: DO NOT USE "0"
A14: Foliar Washoff (cm-1) | B14: 0.5
A15: Molecular Weight (g/mol) | B15: 221.04
A16: Vapor Pressure (torr) | B16: 1.4e-07
A17: Solubility (mg/L) | B17: 569
A18: Henry' Coeefficient (vol/vol) | B18: 2.92e-09
A19: Air Diffusion Coefficient (cm2/day) | C19: This cell may remain blank
A20: Heat of Henry (J/mol) | B20: 50000 | C20: DO NOT USE "0"
A22: logKow | B22: 2.14
A23: Benthic Conversion Factor | B23: =0.37+0.04*D3 -> 0.89
A24: Soil OC fraction for PWC (foc) | B24: 0.04
A26: Terrestrial Animal Foliar Dissipation Halflife Assumption (default assumption 10-days) | B26: 10
A27: Mineau Scaling Factor (default 1.15) | B27: 1.15 | C27: Change this value only if there is chemical specific data to do so

Sheet Plant Residue Data Entry
A1: Enter available emprirical data for residues in the listed matrices. NOTE: These will not override default assumptions. Risk/Impact conclusions will be provided separately for all uses with empirical data.
A3: Use Site (Crosswalked to Use Summary Worksheet) | B3: Empirical residue in pollen/bread (mg a.i./kg) | C3: Empirical residue in nectar (mg a.i./kg) | D3: Empirical residue in foliage (mg a.i./kg) | E3: Empirical residue in jelly (mg a.i./kg)
A4: ='USE SUMMARY TABLE'!B4 -> Corn
A5: ='USE SUMMARY TABLE'!B5 -> Soybean (Glycine max)
A6: ='USE SUMMARY TABLE'!B6 -> Almond
A7: ='USE SUMMARY TABLE'!B7 -> Citrus hybrids, Citrus spp. Eremocitrus spp., Fortunella spp., Microcitrus spp., and Poncirus spp
A8: ='USE SUMMARY TABLE'!B10 -> Garlic, Bulb
A9: ='USE SUMMARY TABLE'!B11 -> Wheat, Triticum spp
A10: ='USE SUMMARY TABLE'!B13 -> Apple
A11: ='USE SUMMARY TABLE'!B14 -> Grass, Pasture
A12: ='USE SUMMARY TABLE'!B15 -> AQUATICS: Water/Fluids/Waste Materials and Systems (Not intended for direct human consumption or food contact)
A13: ='USE SUMMARY TABLE'!B16 -> 0
A14: ='USE SUMMARY TABLE'!B17 -> 0
A15: ='USE SUMMARY TABLE'!B18 -> 0
A16: ='USE SUMMARY TABLE'!B19 -> 0
A17: ='USE SUMMARY TABLE'!B20 -> 0
A18: ='USE SUMMARY TABLE'!B21 -> 0
A19: ='USE SUMMARY TABLE'!B22 -> 0
A20: ='USE SUMMARY TABLE'!B23 -> 0
A21: ='USE SUMMARY TABLE'!B24 -> 0
... A50: ='USE SUMMARY TABLE'!B53 -> 0
A51: ='USE SUMMARY TABLE'!B55 -> TO ADD MORE USES: Copy last row and insert it into this row.

Sheet Lookup Tables For Tool
B1: Color Key: | C1: Surveyed | H1: Application Method | J1: Relative timing | K1: Application Type | M1: Droplet Size Assumption | P1: Foliar or Soil Uptake Assumption | S1: Geographic Definition
C2: Group Name | H2: Ground | J2: Pre-emergence | K2: Spray | M2: Aerial_Fine_50 | P2: Soil Spray | S2: L48
C3: Sub-Group Name | H3: Ground, Aerial | J3: Post-emergence | K3: Spray, Granular | M3: Aerial_Medium | P3: Foliar Spray | S3: L48, NL48
C4: Not Surveyed | H4: Ground, Aerial, Airblast | J4: Pre-Maturity | K4: Spray, Granular, Seed | M4: Aerial_Coarse | P4: soil/granular | S4: NL48
B5: 2 | C5: 2 | H5: Aerial | J5: Post-Maturity | K5: Spray, Seed | M5: Aerial_Very_Coarse | P5: seed
A6: surveyed by anyone and group headings in green | B6: Crop Description IR-4* | H6: Aerial, Airblast | J6: Pre-Removal | K6: Granular | M6: Ground_VF-F_HB
B7: Crop Group/Subgroup | D7: Site | E7: UDL | F7: PWC Scenario | H7: Ground, Airblast | J7: Post-Removal | K7: Granular, Seed | M7: Ground_VF-F_LB
A8: 1 | B8: 1 | C8: 1: Root and Tuber Vegetables Group | D8: 1: Root and Tuber Vegetables Group | E8: see constituent crops | F8: Need constituent crops | H8: Airblast | J8: Absolute Date | K8: Seed | M8: Ground_F-MC_HB
A9: 2 | B9: 1 | C9: Arracacha | D9: Arracacha (Arracacia xanthorrhiza) | E9: Vegetables and Ground Fruit | F9: Vegetable fresh or processing market | M9: Ground_F-MC_LB
A10: 3 | B10: 1 | C10: Arrowroot | D10: Arrowroot (Maranta arundinacea) | E10: Vegetables and Ground Fruit | F10: Vegetable fresh or processing market | M10: Airblast_Sparse
A11: 4 | B11: 1 | C11: Artichoke, Chinese | D11: Artichoke, Chinese (Stachys affinis) | E11: Vegetables and Ground Fruit | F11: Vegetable fresh or processing market
A12: 5 | B12: 1 | C12: Artichoke, Jerusalem | D12: Artichoke, Jerusalem (Helianthus tuberosus) | E12: Vegetables and Ground Fruit | F12: Vegetable fresh or processing market
A13: 6 | B13: 1 | C13: Beet, garden | D13: Beet, garden (Beta vulgaris) | E13: Vegetables and Ground Fruit | F13: Vegetable fresh or processing market
A14: 7 | B14: 1 | C14: Beet, Sugar | D14: Beet, Sugar | E14: Other row crops | F14: Row or field crop
A15: 8 | B15: 1 | C15: Beet, Sugar, Seed | D15: Beet, Sugar, Seed | E15: Other row crops | F15: Row or field crop
A16: 9 | B16: 1 | C16: Burdock, edible | D16: Burdock, edible (Arctium lappa) | E16: Vegetables and Ground Fruit | F16: Vegetable fresh or processing market
A17: 10 | B17: 1 | C17: Canna, edible | D17: Canna, edible (Queensland arrowroot) (Canna indica) | E17: Vegetables and Ground Fruit | F17: Vegetable fresh or processing market
A18: 11 | B18: 1 | C18: Carrot | D18: Carrot (Daucus carota) | E18: Vegetables and Ground Fruit | F18: Vegetable fresh or processing market
A19: 12 | B19: 1 | C19: Cassava, bitter and sweet | D19: Cassava, bitter and sweet (Manihot esculenta) | E19: Vegetables and Ground Fruit | F19: Vegetable fresh or processing market
A20: 13 | B20: 1 | C20: Celeriac | D20: Celeriac (celery root) (Apium graveolens var. rapaceum) | E20: Vegetables and Ground Fruit | F20: Vegetable fresh or processing market
A21: 14 | B21: 1 | C21: Chayote | D21: Chayote (root) (Sechium edule) | E21: Vegetables and Ground Fruit | F21: Vegetable fresh or processing market
A22: 15 | B22: 1 | C22: Chervil, turnip-rooted | D22: Chervil, turnip-rooted (Chaerophyllum bulbosum). | E22: Vegetables and Ground Fruit | F22: Vegetable fresh or processing market
... A45: 38 | B45: 1 | C45: Yam, true | D45: Yam, true (Dioscorea spp.) | E45: Vegetables and Ground Fruit | F45: Vegetable fresh or processing market
A46: 39 | B46: 1A | C46: 1A. Root vegetables subgroup | D46: 1A. Root vegetables subgroup | E46: #N/A | F46: Need constituent crops
A47: 40 | B47: 1A | C47: Beet, garden | D47: Beet, garden | E47: Vegetables and Ground Fruit | F47: Vegetable fresh or processing market
A48: 41 | B48: 1A | C48: Beet, Sugar | D48: Beet, Sugar | E48: Other row crops | F48: Row or field crop
A49: 42 | B49: 1A | C49: Beet, Sugar, Seed | D49: Beet, Sugar, Seed | E49: Other row crops | F49: Row or field crop
A50: 43 | B50: 1A | C50: Burdock, Edible | D50: Burdock, Edible | E50: Vegetables and Ground Fruit | F50: Vegetable fresh or processing market
A51: 44 | B51: 1A | C51: Carrot | D51: Carrot | E51: Vegetables and Ground Fruit | F51: Vegetable fresh or processing market
A52: 45 | B52: 1A | C52: Celeriac | D52: Celeriac | E52: Vegetables and Ground Fruit | F52: Vegetable fresh or processing market
A53: 46 | B53: 1A | C53: Chervil, Turnip-Rooted | D53: Chervil, Turnip-Rooted | E53: Vegetables and Ground Fruit | F53: Vegetable fresh or processing market
A54: 47 | B54: 1A | C54: Chicory | D54: Chicory | E54: Vegetables and Ground Fruit | F54: Vegetable fresh or processing market
A55: 48 | B55: 1A | C55: Ginseng | D55: Ginseng | E55: Vegetables and Ground Fruit | F55: Vegetable fresh or processing market
A56: 49 | B56: 1A | C56: Horseradish | D56: Horseradish | E56: Vegetables and Ground Fruit | F56: Vegetable fresh or processing market
A57: 50 | B57: 1A | C57: Parsley, Turnip-Rooted | D57: Parsley, Turnip-Rooted | E57: Vegetables and Ground Fruit | F57: Vegetable fresh or processing market
A58: 51 | B58: 1A | C58: Parsnip | D58: Parsnip | E58: Vegetables and Ground Fruit | F58: Vegetable fresh or processing market
... A66: 59 | B66: 1A | C66: Turnip | D66: Turnip | E66: Vegetables and Ground Fruit | F66: Vegetable fresh or processing market
A67: 60 | B67: 1B | C67: 1B. Root vegetables | D67: 1B. Root vegetables (except sugar beet) subgroup | E67: #N/A | F67: Need constituent crops
A68: 61 | B68: 1B | C68: Beet, Garden | D68: Beet, Garden | E68: Vegetables and Ground Fruit | F68: Vegetable fresh or processing market
A69: 62 | B69: 1B | C69: Burdock, Edible | D69: Burdock, Edible | E69: Vegetables and Ground Fruit | F69: Vegetable fresh or processing market
...

Sheet summary_TPEZ
A1: RUNOFF+DRIFT ASSUMPTION - Formatted entry of PWC Output for the WPEZ Medians (USED FOR RQs) | E1: RUNOFF ONLY (NO DRIFT) - Formatted entry of PWC Output for the WPEZ Medians (USED FOR MODs)
A2: Run Information | B2: lb/A | E2: Run Information | F2: lb/A
A3: 1_284802-23590-1_Corn-r01-A_USEPA Pond_0010_median | B3: 0.000897 | E3: 1_284802-23590-1_Corn-r01-A_USEPA Pond_0010_median | F3: 0.000897
A4: 1_282174-22397-1_Corn-r02-A_USEPA Pond_0010_median | B4: 0.0001911 | E4: 1_282174-22397-1_Corn-r02-A_USEPA Pond_0010_median | F4: 0.0001911
A5: 1_2493903-15051-1_Corn-r03N-A_USEPA Pond_0010_median | B5: 0.001085 | E5: 1_2493903-15051-1_Corn-r03N-A_USEPA Pond_0010_median | F5: 0.001085
A6: 1_125348-10792-1_Corn-r03S-A_USEPA Pond_0010_median | B6: 0.001668 | E6: 1_125348-10792-1_Corn-r03S-A_USEPA Pond_0010_median | F6: 0.001668
A7: 1_333066-12658-1_Corn-r03W-A_USEPA Pond_0010_median | B7: 0.001779 | E7: 1_333066-12658-1_Corn-r03W-A_USEPA Pond_0010_median | F7: 0.001779
A8: 1_169674-19520-1_Corn-r04-A_USEPA Pond_0010_median | B8: 0.0009003 | E8: 1_169674-19520-1_Corn-r04-A_USEPA Pond_0010_median | F8: 0.0009003
A9: 1_164805-19043-1_Corn-r05-A_USEPA Pond_0010_median | B9: 0.001202 | E9: 1_164805-19043-1_Corn-r05-A_USEPA Pond_0010_median | F9: 0.001202
A10: 1_522893-13848-1_Corn-r06-A_USEPA Pond_0010_median | B10: 0.0009048 | E10: 1_522893-13848-1_Corn-r06-A_USEPA Pond_0010_median | F10: 0.0009048
A11: 1_2765542-21371-1_Corn-r07-A_USEPA Pond_0010_median | B11: 0.001391 | E11: 1_2765542-21371-1_Corn-r07-A_USEPA Pond_0010_median | F11: 0.001391
A12: 1_568322-13597-1_Corn-r08-A_USEPA Pond_0010_median | B12: 0.0004379 | E12: 1_568322-13597-1_Corn-r08-A_USEPA Pond_0010_median | F12: 0.0004379
A13: 1_2798874-27020-1_Corn-r09-A_USEPA Pond_0010_median | B13: 0.00191 | E13: 1_2798874-27020-1_Corn-r09-A_USEPA Pond_0010_median | F13: 0.00191
A14: 1_1691426-20179-13_Corn-r10L-A_USEPA Pond_0010_median | B14: 0.0007045 | E14: 1_1691426-20179-13_Corn-r10L-A_USEPA Pond_0010_median | F14: 0.0007045
... A221: 18_397808-22314-12_Vegetable fresh or processing market-r07-A_USEPA Pond_0010_median | B221: 0.0144 | E221: 31_463577-14897-176_Pasture or forage-r18-A_USEPA Pond_0030_median | F221: 0.004517
A222: 18_1715900-13351-54_Vegetable fresh or processing market-r08-A_USEPA Pond_0010_median | B222: 0.01434
A223: 18_356962-25371-12_Vegetable fresh or processing market-r09-A_USEPA Pond_0010_median | B223: 0.01444
A224: 18_497748-19437-229_Vegetable fresh or processing market-r10L-A_USEPA Pond_0010_median | B224: 0.0145
A225: 18_2517301-22540-12_Vegetable fresh or processing market-r10U-A_USEPA Pond_0010_median | B225: 0.01441
A226: 18_382177-13799-57_Vegetable fresh or processing market-r11-A_USEPA Pond_0010_median | B226: 0.01389
A227: 18_373519-10262-57_Vegetable fresh or processing market-r12-A_USEPA Pond_0010_median | B227: 0.01399
A228: 18_58936-11176-216_Vegetable fresh or processing market-r13-A_USEPA Pond_0010_median | B228: 0.01427
A229: 18_508783-17536-12_Vegetable fresh or processing market-r14-A_USEPA Pond_0010_median | B229: 0.01445
A230: 18_53259-11846-227_Vegetable fresh or processing market-r15-A_USEPA Pond_0010_median | B230: 0.01423
A231: 18_473920-17256-208_Vegetable fresh or processing market-r16-A_USEPA Pond_0010_median | B231: 0.03095
A232: 18_68754-25749-12_Vegetable fresh or processing market-r17-A_USEPA Pond_0010_median | B232: 0.01446
A233: 18_455512-12315-12_Vegetable fresh or processing market-r18-A_USEPA Pond_0010_median | B233: 0.01438
... A415: 30_463577-14897-176_Pasture or forage-r18-A_USEPA Pond_0030_median | B415: 0.02892

Sheet summary_EPA Pond
A1: RUNOFF+DRIFT ASSUMPTION - Formatted entry of PWC Output for the Pond Medians (USED FOR RQs) | O1: RUNOFF ONLY (NO DRIFT) ASSUMPTION - Formatted entry of PWC Output for the Pond Medians (USED FOR MODs) | AR1: RUNOFF ONLY (NO DRIFT) ASSUMPTION | BU1: RUNOFF ONLY (WITH VOLATILITY) ASSUMPTION
A2: Benthic Conversion Factor = 99.38 -Pore water (ug/L) to (total mass | B2: ug)/(dry sed mass | C2: kg) | O2: Benthic Conversion Factor = 13.57 -Pore water (ug/L) to (total mass | P2: ug)/(dry sed mass | Q2: kg)
A3: Run Information | B3: 1-d avg | C3: 365-d avg | D3: Total avg | E3: 4-d avg | F3: 21-d avg | G3: 60-d avg | H3: B 1-day | I3: B 21-d avg | J3: post_bt_avg | K3: throughput | L3: GWpeak | O3: Run Information | P3: 1-d avg | Q3: 365-d avg | R3: Total avg | S3: 4-d avg | T3: 21-d avg | U3: 60-d avg | V3: B 1-day | W3: B 21-d avg | X3: post_bt_avg | Y3: throughput | Z3: GWpeak
A4: 1_284802-23590-1_Corn-r01-A_USEPA Pond_0010_median | B4: 17.13 | C4: 5.519 | D4: 2.616 | E4: 16.98 | F4: 16.11 | G4: 13.9 | H4: 9.026 | I4: 8.988 | J4: NaN | K4: 0.5912 | L4: 1.168e-07 | O4: 1_284802-23590-1_Corn-r01-A_USEPA Pond_0010_median | P4: 17.13 | Q4: 5.519 | R4: 2.616 | S4: 16.98 | T4: 16.11 | U4: 13.9 | V4: 9.026 | W4: 8.988 | X4: NaN | Y4: 0.5912 | Z4: 1.168e-07
A5: 1_282174-22397-1_Corn-r02-A_USEPA Pond_0010_median | B5: 8.715 | C5: 3.15 | D5: 1.179 | E5: 8.641 | F5: 8.172 | G5: 8.068 | H5: 5.468 | I5: 5.456 | J5: 4.377e-06 | K5: 1.329 | L5: 4.667e-06 | O5: 1_282174-22397-1_Corn-r02-A_USEPA Pond_0010_median | P5: 8.715 | Q5: 3.15 | R5: 1.179 | S5: 8.641 | T5: 8.172 | U5: 8.068 | V5: 5.468 | W5: 5.456 | X5: 4.377e-06 | Y5: 1.329 | Z5: 4.667e-06
A6: 1_2493903-15051-1_Corn-r03N-A_USEPA Pond_0010_median | B6: 8.231 | C6: 2.167 | D6: 0.7593 | E6: 8.145 | F6: 7.706 | G6: 6.705 | H6: 4.145 | I6: 4.127 | J6: 1.216e-06 | K6: 1.212 | L6: 1.363e-06 | O6: 1_2493903-15051-1_Corn-r03N-A_USEPA Pond_0010_median | P6: 8.231 | Q6: 2.167 | R6: 0.7593 | S6: 8.145 | T6: 7.706 | U6: 6.705 | V6: 4.145 | W6: 4.127 | X6: 1.216e-06 | Y6: 1.212 | Z6: 1.363e-06
A7: 1_125348-10792-1_Corn-r03S-A_USEPA Pond_0010_median | B7: 9.656 | C7: 2.036 | D7: 0.704 | E7: 9.549 | F7: 8.889 | G7: 7.23 | H7: 4.227 | I7: 4.203 | J7: 1.049e-06 | K7: 1.611 | L7: 1.978e-06 | O7: 1_125348-10792-1_Corn-r03S-A_USEPA Pond_0010_median | P7: 9.656 | Q7: 2.036 | R7: 0.704 | S7: 9.549 | T7: 8.889 | U7: 7.23 | V7: 4.227 | W7: 4.203 | X7: 1.049e-06 | Y7: 1.611 | Z7: 1.978e-06
A8: 1_333066-12658-1_Corn-r03W-A_USEPA Pond_0010_median | B8: 18.48 | C8: 4.265 | D8: 1.742 | E8: 18.22 | F8: 17.43 | G8: 14.75 | H8: 8.855 | I8: 8.808 | J8: 2.085e-05 | K8: 2.01 | L8: 4.001e-05 | O8: 1_333066-12658-1_Corn-r03W-A_USEPA Pond_0010_median | P8: 18.48 | Q8: 4.265 | R8: 1.742 | S8: 18.22 | T8: 17.43 | U8: 14.75 | V8: 8.855 | W8: 8.808 | X8: 2.085e-05 | Y8: 2.01 | Z8: 4.001e-05
A9: 1_169674-19520-1_Corn-r04-A_USEPA Pond_0010_median | B9: 15.19 | C9: 4.252 | D9: 1.964 | E9: 15.07 | F9: 14.31 | G9: 12.36 | H9: 7.755 | I9: 7.722 | J9: NaN | K9: 0.4648 | L9: 1.194e-09 | O9: 1_169674-19520-1_Corn-r04-A_USEPA Pond_0010_median | P9: 15.19 | Q9: 4.252 | R9: 1.964 | S9: 15.07 | T9: 14.31 | U9: 12.36 | V9: 7.755 | W9: 7.722 | X9: NaN | Y9: 0.4648 | Z9: 1.194e-09
A10: 1_164805-19043-1_Corn-r05-A_USEPA Pond_0010_median | B10: 6.116 | C10: 1.527 | D10: 0.6389 | E10: 6.05 | F10: 5.642 | G10: 4.725 | H10: 2.855 | I10: 2.874 | J10: NaN | K10: 0.9491 | L10: 4.488e-07 | O10: 1_164805-19043-1_Corn-r05-A_USEPA Pond_0010_median | P10: 6.116 | Q10: 1.527 | R10: 0.6389 | S10: 6.05 | T10: 5.642 | U10: 4.725 | V10: 2.855 | W10: 2.874 | X10: NaN | Y10: 0.9491 | Z10: 4.488e-07
A11: 1_522893-13848-1_Corn-r06-A_USEPA Pond_0010_median | B11: 13.78 | C11: 3.681 | D11: 1.317 | E11: 13.66 | F11: 13.22 | G11: 11.25 | H11: 7.01 | I11: 6.971 | J11: 1.588e-06 | K11: 2.109 | L11: 2.877e-06 | O11: 1_522893-13848-1_Corn-r06-A_USEPA Pond_0010_median | P11: 13.78 | Q11: 3.681 | R11: 1.317 | S11: 13.66 | T11: 13.22 | U11: 11.25 | V11: 7.01 | W11: 6.971 | X11: 1.588e-06 | Y11: 2.109 | Z11: 2.877e-06
A12: 1_2765542-21371-1_Corn-r07-A_USEPA Pond_0010_median | B12: 6.796 | C12: 1.983 | D12: 0.8371 | E12: 6.767 | F12: 6.504 | G12: 5.72 | H12: 3.626 | I12: 3.667 | J12: NaN | K12: 0.512 | L12: 3.784e-07 | O12: 1_2765542-21371-1_Corn-r07-A_USEPA Pond_0010_median | P12: 6.796 | Q12: 1.983 | R12: 0.8371 | S12: 6.767 | T12: 6.504 | U12: 5.72 | V12: 3.626 | W12: 3.667 | X12: NaN | Y12: 0.512 | Z12: 3.784e-07
A13: 1_568322-13597-1_Corn-r08-A_USEPA Pond_0010_median | B13: 18.7 | C13: 4.514 | D13: 1.83 | E13: 18.5 | F13: 17.68 | G13: 15.11 | H13: 9.44 | I13: 9.394 | J13: 3.816e-06 | K13: 1.125 | L13: 5.445e-06 | O13: 1_568322-13597-1_Corn-r08-A_USEPA Pond_0010_median | P13: 18.7 | Q13: 4.514 | R13: 1.83 | S13: 18.5 | T13: 17.68 | U13: 15.11 | V13: 9.44 | W13: 9.394 | X13: 3.816e-06 | Y13: 1.125 | Z13: 5.445e-06
A14: 1_2798874-27020-1_Corn-r09-A_USEPA Pond_0010_median | B14: 6.866 | C14: 2.102 | D14: 0.7515 | E14: 6.812 | F14: 6.482 | G14: 5.676 | H14: 3.575 | I14: 3.561 | J14: NaN | K14: 0.2369 | L14: 4.615e-11 | O14: 1_2798874-27020-1_Corn-r09-A_USEPA Pond_0010_median | P14: 6.866 | Q14: 2.102 | R14: 0.7515 | S14: 6.812 | T14: 6.482 | U14: 5.676 | V14: 3.575 | W14: 3.561 | X14: NaN | Y14: 0.2369 | Z14: 4.615e-11
A15: 1_1691426-20179-13_Corn-r10L-A_USEPA Pond_0010_median | B15: 9.337 | C15: 2.424 | D15: 0.8901 | E15: 9.228 | F15: 8.737 | G15: 7.452 | H15: 4.692 | I15: 4.667 | J15: NaN | K15: 0.3861 | L15: 2.766e-08 | O15: 1_1691426-20179-13_Corn-r10L-A_USEPA Pond_0010_median | P15: 9.337 | Q15: 2.424 | R15: 0.8901 | S15: 9.228 | T15: 8.737 | U15: 7.452 | V15: 4.692 | W15: 4.667 | X15: NaN | Y15: 0.3861 | Z15: 2.766e-08
A16: 1_418822-23009-1_Corn-r10U-A_USEPA Pond_0010_median | B16: 5.976 | C16: 1.748 | D16: 0.5308 | E16: 5.919 | F16: 5.618 | G16: 4.795 | H16: 3.159 | I16: 3.185 | J16: NaN | K16: 0.04494 | L16: 6.021e-21 | O16: 1_418822-23009-1_Corn-r10U-A_USEPA Pond_0010_median | P16: 5.976 | Q16: 1.748 | R16: 0.5308 | S16: 5.919 | T16: 5.618 | U16: 4.795 | V16: 3.159 | W16: 3.185 | X16: NaN | Y16: 0.04494 | Z16: 6.021e-21
A17: 1_1380629-16622-1_Corn-r11-A_USEPA Pond_0010_median | B17: 5.046 | C17: 1.164 | D17: 0.3795 | E17: 4.993 | F17: 4.771 | G17: 4.01 | H17: 2.38 | I17: 2.366 | J17: NaN | K17: 0.004943 | L17: 7.733e-30 | O17: 1_1380629-16622-1_Corn-r11-A_USEPA Pond_0010_median | P17: 5.046 | Q17: 1.164 | R17: 0.3795 | S17: 4.993 | T17: 4.771 | U17: 4.01 | V17: 2.38 | W17: 2.366 | X17: NaN | Y17: 0.004943 | Z17: 7.733e-30
A18: 1_372423-12152-1_Corn-r12-A_USEPA Pond_0010_median | B18: 7.012 | C18: 1.429 | D18: 0.5272 | E18: 6.913 | F18: 6.397 | G18: 5.309 | H18: 3.119 | I18: 3.102 | J18: NaN | K18: 0.3569 | L18: 2.116e-08 | O18: 1_372423-12152-1_Corn-r12-A_USEPA Pond_0010_median | P18: 7.012 | Q18: 1.429 | R18: 0.5272 | S18: 6.913 | T18: 6.397 | U18: 5.309 | V18: 3.119 | W18: 3.102 | X18: NaN | Y18: 0.3569 | Z18: 2.116e-08
A19: 1_55992-12595-237_Corn-r13-A_USEPA Pond_0010_median | B19: 0.2533 | C19: 0.07623 | D19: 0.03862 | E19: 0.2472 | F19: 0.2316 | G19: 0.2434 | H19: 0.2195 | I19: 0.2317 | J19: NaN | K19: 0.007153 | L19: 4.151e-38 | O19: 1_55992-12595-237_Corn-r13-A_USEPA Pond_0010_median | P19: 0.2533 | Q19: 0.07623 | R19: 0.03862 | S19: 0.2472 | T19: 0.2316 | U19: 0.2434 | V19: 0.2195 | W19: 0.2317 | X19: NaN | Y19: 0.007153 | Z19: 4.151e-38
A20: 1_506809-18005-1_Corn-r14-A_USEPA Pond_0010_median | B20: 2.502 | C20: 0.9707 | D20: 0.2878 | E20: 2.492 | F20: 2.397 | G20: 2.142 | H20: 1.862 | I20: 1.861 | J20: NaN | K20: 0.0101 | L20: 6.334e-33 | O20: 1_506809-18005-1_Corn-r14-A_USEPA Pond_0010_median | P20: 2.502 | Q20: 0.9707 | R20: 0.2878 | S20: 2.492 | T20: 2.397 | U20: 2.142 | V20: 1.862 | W20: 1.861 | X20: NaN | Y20: 0.0101 | Z20: 6.334e-33
A21: 1_54973-11158-226_Corn-r15-A_USEPA Pond_0010_median | B21: 0.09752 | C21: 0.0323 | D21: 0.01411 | E21: 0.09822 | F21: 0.101 | G21: 0.1135 | H21: 0.1091 | I21: 0.1159 | J21: NaN | K21: 0.001072 | L21: 3.371e-81 | O21: 1_54973-11158-226_Corn-r15-A_USEPA Pond_0010_median | P21: 0.09752 | Q21: 0.0323 | R21: 0.01411 | S21: 0.09822 | T21: 0.101 | U21: 0.1135 | V21: 0.1091 | W21: 0.1159 | X21: NaN | Y21: 0.001072 | Z21: 3.371e-81
A22: 1_481578-20116-1_Corn-r16-A_USEPA Pond_0010_median | B22: 9.264 | C22: 3.121 | D22: 0.9988 | E22: 9.222 | F22: 8.925 | G22: 8.132 | H22: 5.368 | I22: 5.346 | J22: NaN | K22: 0.08712 | L22: 4.817e-19 | O22: 1_481578-20116-1_Corn-r16-A_USEPA Pond_0010_median | P22: 9.264 | Q22: 3.121 | R22: 0.9988 | S22: 9.222 | T22: 8.925 | U22: 8.132 | V22: 5.368 | W22: 5.346 | X22: NaN | Y22: 0.08712 | Z22: 4.817e-19
A23: 1_69526-24571-1_Corn-r17-A_USEPA Pond_0010_median | B23: 0.3009 | C23: 0.1198 | D23: 0.04034 | E23: 0.298 | F23: 0.2822 | G23: 0.2517 | H23: 0.244 | I23: 0.2484 | J23: NaN | K23: 0.005415 | L23: 1.475e-38 | O23: 1_69526-24571-1_Corn-r17-A_USEPA Pond_0010_median | P23: 0.3009 | Q23: 0.1198 | R23: 0.04034 | S23: 0.298 | T23: 0.2822 | U23: 0.2517 | V23: 0.244 | W23: 0.2484 | X23: NaN | Y23: 0.005415 | Z23: 1.475e-38
A24: 1_467176-15131-225_Corn-r18-A_USEPA Pond_0010_median | B24: 8.02e-05 | C24: 2.095e-05 | D24: 1.465e-05 | E24: 7.884e-05 | F24: 7.316e-05 | G24: 5.784e-05 | H24: 3.564e-05 | I24: 3.679e-05 | J24: NaN | K24: 0.005805 | L24: 4.347e-42 | O24: 1_467176-15131-225_Corn-r18-A_USEPA Pond_0010_median | P24: 8.02e-05 | Q24: 2.095e-05 | R24: 1.465e-05 | S24: 7.884e-05 | T24: 7.316e-05 | U24: 5.784e-05 | V24: 3.564e-05 | W24: 3.679e-05 | X24: NaN | Y24: 0.005805 | Z24: 4.347e-42
A25: 2_284802-23590-1_Corn-r01-A_USEPA Pond_0010_median | B25: 19.06 | C25: 6.23 | D25: 3.337 | E25: 18.9 | F25: 17.99 | G25: 15.52 | H25: 10.12 | I25: 10.08 | J25: NaN | K25: 0.5912 | L25: 1.164e-07 | O25: 5_284802-23590-1_Corn-r01-A_USEPA Pond_0010_median | P25: 17.13 | Q25: 5.519 | R25: 2.616 | S25: 16.98 | T25: 16.11 | U25: 13.9 | V25: 9.026 | W25: 8.988 | X25: NaN | Y25: 0.5912 | Z25: 1.168e-07
A26: 2_282174-22397-1_Corn-r02-A_USEPA Pond_0010_median | B26: 10.74 | C26: 3.823 | D26: 1.86 | E26: 10.65 | F26: 10.07 | G26: 8.796 | H26: 6.416 | I26: 6.44 | J26: 4.358e-06 | K26: 1.329 | L26: 4.648e-06 | O26: 5_282174-22397-1_Corn-r02-A_USEPA Pond_0010_median | P26: 8.715 | Q26: 3.15 | R26: 1.179 | S26: 8.641 | T26: 8.172 | U26: 8.068 | V26: 5.468 | W26: 5.456 | X26: 4.377e-06 | Y26: 1.329 | Z26: 4.667e-06
A27: 2_2493903-15051-1_Corn-r03N-A_USEPA Pond_0010_median | B27: 10.03 | C27: 2.657 | D27: 1.262 | E27: 9.929 | F27: 9.385 | G27: 8.153 | H27: 5.067 | I27: 5.045 | J27: 1.211e-06 | K27: 1.212 | L27: 1.358e-06 | O27: 5_2493903-15051-1_Corn-r03N-A_USEPA Pond_0010_median | P27: 8.231 | Q27: 2.167 | R27: 0.7593 | S27: 8.145 | T27: 7.706 | U27: 6.705 | V27: 4.145 | W27: 4.127 | X27: 1.216e-06 | Y27: 1.212 | Z27: 1.363e-06
A28: 2_125348-10792-1_Corn-r03S-A_USEPA Pond_0010_median | B28: 11.41 | C28: 2.413 | D28: 1.086 | E28: 11.26 | F28: 10.45 | G28: 8.495 | H28: 5.016 | I28: 4.987 | J28: 1.044e-06 | K28: 1.611 | L28: 1.969e-06 | O28: 5_125348-10792-1_Corn-r03S-A_USEPA Pond_0010_median | P28: 9.656 | Q28: 2.036 | R28: 0.704 | S28: 9.549 | T28: 8.889 | U28: 7.23 | V28: 4.227 | W28: 4.203 | X28: 1.049e-06 | Y28: 1.611 | Z28: 1.978e-06
A29: 2_333066-12658-1_Corn-r03W-A_USEPA Pond_0010_median | B29: 20.18 | C29: 4.669 | D29: 2.16 | E29: 19.89 | F29: 18.98 | G29: 16.05 | H29: 9.666 | I29: 9.615 | J29: 2.076e-05 | K29: 2.01 | L29: 3.984e-05 | O29: 5_333066-12658-1_Corn-r03W-A_USEPA Pond_0010_median | P29: 18.48 | Q29: 4.265 | R29: 1.742 | S29: 18.22 | T29: 17.43 | U29: 14.75 | V29: 8.855 | W29: 8.808 | X29: 2.085e-05 | Y29: 2.01 | Z29: 4.001e-05
A30: 2_169674-19520-1_Corn-r04-A_USEPA Pond_0010_median | B30: 17 | C30: 4.761 | D30: 2.501 | E30: 16.81 | F30: 16.02 | G30: 13.83 | H30: 8.688 | I30: 8.651 | J30: NaN | K30: 0.4648 | L30: 1.189e-09 | O30: 5_169674-19520-1_Corn-r04-A_USEPA Pond_0010_median | P30: 15.19 | Q30: 4.252 | R30: 1.964 | S30: 15.07 | T30: 14.31 | U30: 12.36 | V30: 7.755 | W30: 7.722 | X30: NaN | Y30: 0.4648 | Z30: 1.194e-09
A31: 2_164805-19043-1_Corn-r05-A_USEPA Pond_0010_median | B31: 7.99 | C31: 2.037 | D31: 1.151 | E31: 7.893 | F31: 7.348 | G31: 6.151 | H31: 3.789 | I31: 3.772 | J31: NaN | K31: 0.9491 | L31: 4.469e-07 | O31: 5_164805-19043-1_Corn-r05-A_USEPA Pond_0010_median | P31: 6.116 | Q31: 1.527 | R31: 0.6389 | S31: 6.05 | T31: 5.642 | U31: 4.725 | V31: 2.855 | W31: 2.874 | X31: NaN | Y31: 0.9491 | Z31: 4.488e-07
A32: 2_522893-13848-1_Corn-r06-A_USEPA Pond_0010_median | B32: 15.57 | C32: 4.146 | D32: 1.785 | E32: 15.43 | F32: 14.91 | G32: 12.67 | H32: 7.896 | I32: 7.852 | J32: 1.582e-06 | K32: 2.109 | L32: 2.865e-06 | O32: 5_522893-13848-1_Corn-r06-A_USEPA Pond_0010_median | P32: 13.78 | Q32: 3.681 | R32: 1.317 | S32: 13.66 | T32: 13.22 | U32: 11.25 | V32: 7.01 | W32: 6.971 | X32: 1.588e-06 | Y32: 2.109 | Z32: 2.877e-06
A33: 2_2765542-21371-1_Corn-r07-A_USEPA Pond_0010_median | B33: 8.666 | C33: 2.543 | D33: 1.419 | E33: 8.572 | F33: 8.291 | G33: 7.253 | H33: 4.555 | I33: 4.636 | J33: NaN | K33: 0.512 | L33: 3.768e-07 | O33: 5_2765542-21371-1_Corn-r07-A_USEPA Pond_0010_median | P33: 6.796 | Q33: 1.983 | R33: 0.8371 | S33: 6.767 | T33: 6.504 | U33: 5.72 | V33: 3.626 | W33: 3.667 | X33: NaN | Y33: 0.512 | Z33: 3.784e-07
A34: 2_568322-13597-1_Corn-r08-A_USEPA Pond_0010_median | B34: 20.35 | C34: 4.942 | D34: 2.26 | E34: 20.22 | F34: 19.29 | G34: 16.45 | H34: 10.32 | I34: 10.27 | J34: 3.8e-06 | K34: 1.125 | L34: 5.421e-06 | O34: 5_568322-13597-1_Corn-r08-A_USEPA Pond_0010_median | P34: 18.7 | Q34: 4.514 | R34: 1.83 | S34: 18.5 | T34: 17.68 | U34: 15.11 | V34: 9.44 | W34: 9.394 | X34: 3.816e-06 | Y34: 1.125 | Z34: 5.445e-06
A35: 2_2798874-27020-1_Corn-r09-A_USEPA Pond_0010_median | B35: 8.902 | C35: 2.831 | D35: 1.477 | E35: 8.832 | F35: 8.405 | G35: 7.361 | H35: 4.771 | I35: 4.752 | J35: NaN | K35: 0.2369 | L35: 4.595e-11 | O35: 5_2798874-27020-1_Corn-r09-A_USEPA Pond_0010_median | P35: 6.866 | Q35: 2.102 | R35: 0.7515 | S35: 6.812 | T35: 6.482 | U35: 5.676 | V35: 3.575 | W35: 3.561 | X35: NaN | Y35: 0.2369 | Z35: 4.615e-11
